2025-04-02 16:28:02 - INFO [root:448] - 02-04-2025 16:27:59	handle_transcribe	/transcribe	SUCCESS	Audio: 0.942s - Gemini: 1.599s - Tổng: 2.544s	426	Mozilla/5.0 (Macintosh; Intel Mac OS X 10_15_7) AppleWebKit/537.36 (KHTML, like Gecko) Chrome/134.0.0.0 Safari/537.36	{"audio_file": "blob", "client_ip": "127.0.0.1", "text": "bao vani một cái"}	Kết quả: {"products": [{"name": "Bánh Bao Thọ Phát KN Cua Xanh Vani 260g(65gx4)", "quantity": 1, "sapCode": "5000095", "description": "Khớp 100% với yêu cầu: cua xanh, vani, 260g"}], "order_status": "new", "total_items": 1, "created_at": "2025-04-02T16:28:02.446969", "updated_at": "2025-04-02T16:28:02.446920", "message": "Đã cập nhật đơn hàng", "spoken_text": "bao vani một cái"}
2025-04-02 16:29:05 - ERROR [root:348] - Lỗi khi xử lý audio: 
2025-04-02 16:29:05 - ERROR [root:349] - Traceback (most recent call last):
  File "/Users/phungduong/Documents/Kido Documents/python/VoiceToJson/server.py", line 340, in transcribe_audio
    text = recognizer.recognize_google(audio_data, language="vi-VN")
  File "/Users/phungduong/Documents/Kido Documents/Kido_Project/face-client/venv/lib/python3.10/site-packages/speech_recognition/recognizers/google.py", line 262, in recognize_legacy
    return output_parser.parse(response_text)
  File "/Users/phungduong/Documents/Kido Documents/Kido_Project/face-client/venv/lib/python3.10/site-packages/speech_recognition/recognizers/google.py", line 134, in parse
    actual_result = self.convert_to_result(response_text)
  File "/Users/phungduong/Documents/Kido Documents/Kido_Project/face-client/venv/lib/python3.10/site-packages/speech_recognition/recognizers/google.py", line 183, in convert_to_result
    raise UnknownValueError()
speech_recognition.exceptions.UnknownValueError

2025-04-02 16:29:05 - ERROR [root:467] - 02-04-2025 16:29:04	handle_transcribe	/transcribe	ERROR	Audio: 0.000s - Gemini: 0.000s - Tổng: 0.498s	0	Mozilla/5.0 (Macintosh; Intel Mac OS X 10_15_7) AppleWebKit/537.36 (KHTML, like Gecko) Chrome/134.0.0.0 Safari/537.36	{"error": "", "client_ip": "127.0.0.1"}	Kết quả: {"error": ""}
2025-04-02 16:29:05 - ERROR [root:468] - Exception details: 
2025-04-02 16:29:05 - ERROR [root:471] - Lỗi khi xử lý audio:
Traceback (most recent call last):
  File "/Users/phungduong/Documents/Kido Documents/python/VoiceToJson/server.py", line 418, in handle_transcribe
    text = transcribe_audio(audio_file)
  File "/Users/phungduong/Documents/Kido Documents/python/VoiceToJson/server.py", line 340, in transcribe_audio
    text = recognizer.recognize_google(audio_data, language="vi-VN")
  File "/Users/phungduong/Documents/Kido Documents/Kido_Project/face-client/venv/lib/python3.10/site-packages/speech_recognition/recognizers/google.py", line 262, in recognize_legacy
    return output_parser.parse(response_text)
  File "/Users/phungduong/Documents/Kido Documents/Kido_Project/face-client/venv/lib/python3.10/site-packages/speech_recognition/recognizers/google.py", line 134, in parse
    actual_result = self.convert_to_result(response_text)
  File "/Users/phungduong/Documents/Kido Documents/Kido_Project/face-client/venv/lib/python3.10/site-packages/speech_recognition/recognizers/google.py", line 183, in convert_to_result
    raise UnknownValueError()
speech_recognition.exceptions.UnknownValueError
